<?xml version="1.0"?>
<robot xmlns:xacro="http://www.ros.org/wiki/xacro" name="stretch_main">
  <xacro:property name="M_PI" value="3.1415926535897931" /> 

  <xacro:property name="joint_damping" value="21.75"/>
  <xacro:property name="joint_friction" value="10.48"/>
  <xacro:property name="joint_spring_stiffness" value="0"/>
  <xacro:property name="joint_spring_reference" value="0"/>
  <xacro:property name="caster_damping" value="0.005"/>
  <xacro:property name="caster_friction" value="0.001"/>
  <xacro:property name="caster_velocity_limit" value="5.0"/>
  <xacro:property name="caster_effort_limit" value="100"/>

  <link
    name="base_link">
    <inertial>
      <origin
        xyz="-0.109461304328163 -0.000741018909047708 0.0914915269429946"
        rpy="0 0 0" />
      <mass
        value="1.0723782659782" />
      <inertia
        ixx="0.00310580907710135"
        ixy="1.5182848191076E-06"
        ixz="0.00041690466732394"
        iyy="0.00433798719991832"
        iyz="1.33487716258445E-05"
        izz="0.0037204727467362" />
    </inertial>
    <visual>
      <origin
        xyz="0 0 0"
        rpy="0 0 0" />
      <geometry>
        <mesh
          filename="package://stretch_description/meshes/base_link.dae" />
      </geometry>
    </visual>
    <collision>
      <origin
        xyz="0 0 0"
        rpy="0 0 0" />
      <geometry>
        <mesh
          filename="package://stretch_description/meshes/base_link.STL" />
      </geometry>
    </collision>
  </link>
  
  <link
    name="link_right_wheel">
    <inertial>
      <origin
        xyz="1.25554620866719E-07 3.54748938447003E-07 0.0239581106165018"
        rpy="0 0 0" />
      <mass
        value="0.00356714564938475" />
      <inertia
        ixx="0.001"
        ixy="0"
        ixz="0"
        iyy="0.001"
        iyz="0"
        izz="0.001" />
    </inertial>
    <visual>
      <origin
        xyz="0 0 0"
        rpy="0 0 0" />
      <geometry>
        <mesh
          filename="package://stretch_description/meshes/link_right_wheel.dae" />
      </geometry>
    </visual>
    <collision>
      <origin
        xyz="0 0 0"
        rpy="0 0 0" />
      <geometry>
        <mesh
          filename="package://stretch_description/meshes/link_right_wheel.STL" />
      </geometry>
    </collision>
  </link>
  
  <joint
    name="joint_right_wheel"
    type="continuous">
    <origin
      xyz="-0.00300000000000034 -0.15765 0.0508000000000004"
      rpy="-1.57079632679489 -1.11022302462516E-16 7.28583859910277E-17" />
    <parent
      link="base_link" />
    <child
      link="link_right_wheel" />
    <axis
      xyz="0 0 1" />
      <dynamics damping="${joint_damping}" friction="${joint_friction}" spring_reference="${joint_spring_reference}" spring_stiffness="{joint_spring_stiffness}"/>
  </joint>
  
  <link
    name="link_left_wheel">
    <inertial>
      <origin
        xyz="1.2555462092223E-07 -3.54748938502514E-07 -0.0239581106165035"
        rpy="0 0 0" />
      <mass
        value="0.00356714564938459" />
      <inertia
        ixx="0.001"
        ixy="0"
        ixz="0"
        iyy="0.001"
        iyz="0"
        izz="0.001" />
    </inertial>
    <visual>
      <origin
        xyz="0 0 0"
        rpy="0 0 0" />
      <geometry>
        <mesh
          filename="package://stretch_description/meshes/link_left_wheel.dae" />
      </geometry>
    </visual>
    <collision>
      <origin
        xyz="0 0 0"
        rpy="0 0 0" />
      <geometry>
        <mesh
          filename="package://stretch_description/meshes/link_left_wheel.STL" />
      </geometry>
    </collision>
  </link>
  
  <joint
    name="joint_left_wheel"
    type="continuous">
    <origin
      xyz="-0.00300000000001899 0.15765 0.0507999999999994"
      rpy="-1.5707963267949 3.16227047920818E-31 7.88745438253713E-16" />
    <parent
      link="base_link" />
    <child
      link="link_left_wheel" />
    <axis
      xyz="0 0 1" />
      <dynamics damping="${joint_damping}" friction="${joint_friction}" spring_reference="${joint_spring_reference}" spring_stiffness="{joint_spring_stiffness}"/>
  </joint>

  <!-- Representing a ball joint -->
  <!-- <joint name="caster_joint_theta" type="continuous">
    <origin xyz="-0.245 0.0 0.032" rpy="${-M_PI/2} 0 0"/>
    <parent link="base_link"/>
    <child link="caster_link_theta"/>
    <axis xyz="0 1 0" />
    <dynamics friction="${caster_friction}" damping="${caster_damping}" />
    <limit lower="${-pi/2}" upper="${-pi/2}" velocity="${caster_velocity_limit}" effort="${caster_effort_limit}" />
  </joint>

  <link name="caster_link_theta">
    <inertial>
      <mass value="0.0025" />
      <inertia ixx="5.8083e-4" ixy="0" ixz="0" iyy="3.0833e-5" iyz="0" izz="5.9083e-4" />
    </inertial>
  </link>

  <joint name="caster_joint_psi" type="continuous">
    <parent link="caster_link_theta"/>
    <child link="caster_link_psi"/>
    <axis xyz="0 0 1" />
    <dynamics friction="${caster_friction}" damping="${caster_damping}" />
    <limit lower="${-pi/2}" upper="${-pi/2}" velocity="${caster_velocity_limit}" effort="${caster_effort_limit}" />
  </joint>

  <link name="caster_link_psi">
    <inertial>
      <mass value="0.0025" />
      <inertia ixx="5.8083e-4" ixy="0" ixz="0" iyy="3.0833e-5" iyz="0" izz="5.9083e-4" />
    </inertial>  
  </link>

  <joint name="caster_joint_phi" type="continuous">
    <parent link="caster_link_theta"/>
    <child link="caster_link_phi"/>
    <axis xyz="1 0 0" />
    <dynamics friction="${caster_friction}" damping="${caster_damping}" />
  </joint>

  <link name="caster_link_phi">
    <inertial>
      <mass value="0.0025" />
      <inertia ixx="5.8083e-4" ixy="0" ixz="0" iyy="3.0833e-5" iyz="0" izz="5.9083e-4" />
      <limit lower="${-pi/2}" upper="${-pi/2}" velocity="${caster_velocity_limit}" effort="${caster_effort_limit}" />
    </inertial>  
  </link> -->

  <link name="link_caster">
    <collision>
      <geometry>
        <sphere radius="0.032"/>
      </geometry>
      <origin rpy="0 0 0" xyz="0 0 0"/>
      <surface>
        <friction>
          <ode>
            <mu>0</mu>
            <mu2>0</mu2>
            <slip1>1.0</slip1>
            <slip2>1.0</slip2>
          </ode>
        </friction>
        <contact>
          <ode>
            <soft_cfm>0</soft_cfm>
            <soft_erp>0.2</soft_erp>
            <kp>1e+13</kp>
            <kd>1</kd>
            <min_depth>0.001</min_depth>
          </ode>
        </contact>
      </surface>
    </collision>
    <visual>
      <origin
        xyz="0 0 0"
        rpy="0 0 0" />
      <geometry>
        <mesh
          filename="package://stretch_description/meshes/omni_wheel_m.dae" />
      </geometry>
    </visual>
    <inertial>
      <mass value="0.01" />
      <origin xyz="0 0 0" />
      <inertia
        ixx="0.001"
        ixy="0"
        ixz="0"
        iyy="0.001"
        iyz="0"
        izz="0.001" />
    </inertial>
  </link>

  <joint name="joint_caster" type="fixed">
    <!-- <parent link="caster_link_phi"/> -->
    <parent link="base_link"/>
    <child link="link_caster"/>
    <origin xyz="-0.245 0.0 0.032" rpy="${-M_PI/2} 0 0"/>
  </joint>


  <link
    name="link_mast">
    <inertial>
      <origin
        xyz="-0.109461304328163 -0.000741018909047708 0.0914915269429946"
        rpy="0 0 0" />
      <mass
        value="0.05" />
      <inertia
        ixx="0.001"
        ixy="0.0"
        ixz="0.0"
        iyy="0.001"
        iyz="0.0"
        izz="0.001" />
    </inertial>
    <visual>
      <origin
        xyz="0 0 0"
        rpy="0 0 0" />
      <geometry>
        <mesh
          filename="package://stretch_description/meshes/link_mast.dae" />
      </geometry>
    </visual>
    <collision>
      <origin
        xyz="0 0 0"
        rpy="0 0 0" />
      <geometry>
        <mesh
          filename="package://stretch_description/meshes/link_mast.STL" />
      </geometry>
    </collision>
  </link>
  
  <joint
    name="joint_mast"
    type="fixed">
    <origin
      xyz="-0.07 0.134999999999998 0.0284000000000001"
      rpy="1.5707963267949 0 0.00925318926571245" />
    <parent
      link="base_link" />
    <child
      link="link_mast" />
    <axis
      xyz="0 0 0" />
  </joint>

  <link
    name="link_lift">
    <inertial>
      <origin
        xyz="-0.0547636346252869 0.0380939689802074 0.00933159404448308"
        rpy="0 0 0" />
      <mass
        value="0.044820831236007" />
      <inertia
        ixx="0.001"
        ixy="0.0"
        ixz="0.0"
        iyy="0.001"
        iyz="0.0"
        izz="0.001" />
    </inertial>
    <visual>
      <origin
        xyz="0 0 0"
        rpy="0 0 0" />
      <geometry>
        <mesh
          filename="package://stretch_description/meshes/link_lift.dae" />
      </geometry>
    </visual>
    <collision>
      <origin
        xyz="0 0 0"
        rpy="0 0 0" />
      <geometry>
        <mesh
          filename="package://stretch_description/meshes/link_lift.STL" />
      </geometry>
    </collision>
  </link>
  
  <joint
    name="joint_lift"
    type="prismatic">
    <origin
      xyz="-0.0369217062323472 0.266771199999996 -0.000341653286793524"
      rpy="-1.57079632679552 1.5615431375292 -6.2942004366467E-13" />
    <parent
      link="link_mast" />
    <child
      link="link_lift" />
    <axis
  xyz="0 0 1" />
    <limit effort="100" lower="-0.1033" upper="0.9967" velocity="1.0"/>
    <!-- Make this high friction so gripper does not fall -->
    <dynamics damping="10" friction="10.48" spring_reference="${joint_spring_reference}" spring_stiffness="{joint_spring_stiffness}"/>
  </joint>
  
  <link
    name="link_arm_l4">
    <inertial>
      <origin
        xyz="-1.61247276464493E-06 1.54715589201215E-06 -0.0953252706040035"
        rpy="0 0 0" />
      <mass
        value="0.00676525455789735" />
      <inertia
        ixx="0.001"
        ixy="0"
        ixz="0"
        iyy="0.001"
        iyz="0"
        izz="0.001" />
    </inertial>
    <visual>
      <origin
        xyz="0 0 0"
        rpy="0 0 0" />
      <geometry>
        <mesh
          filename="package://stretch_description/meshes/link_arm_l4.dae" />
      </geometry>
    </visual>
    <collision>
      <origin
        xyz="0 0 0"
        rpy="0 0 0" />
      <geometry>
        <mesh
          filename="package://stretch_description/meshes/link_arm_l4.STL" />
      </geometry>
    </collision>
  </link>
  
  <joint
    name="joint_arm_l4"
    type="fixed">
    <origin
      xyz="-0.25471 0 0"
      rpy="1.5708 -3.1019E-16 -1.5708" />
    <parent
      link="link_lift" />
    <child
      link="link_arm_l4" />
    <axis
      xyz="0 0 0" />
  </joint>
  
  <link
    name="link_arm_l3">
    <inertial>
      <origin
        xyz="-3.34873468621488E-07 4.7411336306924E-07 -0.0974069598289041"
        rpy="0 0 0" />
      <mass
        value="0.00626921047058405" />
      <inertia
        ixx="0.001"
        ixy="0"
        ixz="0"
        iyy="0.001"
        iyz="0"
        izz="0.001" />
    </inertial>
    <visual>
      <origin
        xyz="0 0 0"
        rpy="0 0 0" />
      <geometry>
        <mesh
          filename="package://stretch_description/meshes/link_arm_l3.dae" />
      </geometry>
    </visual>
    <collision>
      <origin
        xyz="0 0 0"
        rpy="0 0 0" />
      <geometry>
        <mesh
          filename="package://stretch_description/meshes/link_arm_l3.STL" />
      </geometry>
    </collision>
  </link>
  
  <joint
    name="joint_arm_l3"
    type="prismatic">
    <origin
      xyz="0 0 0.013"
      rpy="3.5742E-16 3.2123E-16 -2.4565E-16" />
    <parent
      link="link_arm_l4" />
    <child
      link="link_arm_l3" />
    <axis
  xyz="0 0 1" />
    <limit effort="100" lower="0.0" upper="0.13" velocity="1.0"/>
    <dynamics damping="${joint_damping}" friction="${joint_friction}" spring_reference="${joint_spring_reference}" spring_stiffness="{joint_spring_stiffness}"/>
  </joint>
  
  <link
    name="link_arm_l2">
    <inertial>
      <origin
        xyz="-3.31043560508615E-07 3.13422303999111E-07 -0.097255883541891"
        rpy="0 0 0" />
      <mass
        value="0.00569074368576238" />
      <inertia
        ixx="0.001"
        ixy="0"
        ixz="0"
        iyy="0.001"
        iyz="0"
        izz="0.001" />
    </inertial>
    <visual>
      <origin
        xyz="0 0 0"
        rpy="0 0 0" />
      <geometry>
        <mesh
          filename="package://stretch_description/meshes/link_arm_l2.dae" />
      </geometry>
    </visual>
    <collision>
      <origin
        xyz="0 0 0"
        rpy="0 0 0" />
      <geometry>
        <mesh
          filename="package://stretch_description/meshes/link_arm_l2.STL" />
      </geometry>
    </collision>
  </link>

  <joint
    name="joint_arm_l2"
    type="prismatic">
    <origin
      xyz="0 0 0.013"
      rpy="2.91385731014123E-16 4.44300759504684E-17 3.25691080516352E-16" />
    <parent
      link="link_arm_l3" />
    <child
      link="link_arm_l2" />
    <axis
  xyz="0 0 1" />
    <limit effort="100" lower="0.0" upper="0.13" velocity="1.0"/>
    <dynamics damping="${joint_damping}" friction="${joint_friction}" spring_reference="${joint_spring_reference}" spring_stiffness="{joint_spring_stiffness}"/>
  </joint>
  
  <link
    name="link_arm_l1">
    <inertial>
      <origin
        xyz="-3.36876635420591E-07 3.05876091066803E-07 -0.0969117032232756"
        rpy="0 0 0" />
      <mass
        value="0.00511763619538321" />
      <inertia
        ixx="0.001"
        ixy="0"
        ixz="0"
        iyy="0.001"
        iyz="0"
        izz="0.001" />
    </inertial>
    <visual>
      <origin
        xyz="0 0 0"
        rpy="0 0 0" />
      <geometry>
        <mesh
          filename="package://stretch_description/meshes/link_arm_l1.dae" />
      </geometry>
    </visual>
    <collision>
      <origin
        xyz="0 0 0"
        rpy="0 0 0" />
      <geometry>
        <mesh
          filename="package://stretch_description/meshes/link_arm_l1.STL" />
      </geometry>
    </collision>
  </link>
  
  <joint
    name="joint_arm_l1"
    type="prismatic">
    <origin
      xyz="0 0 0.013"
      rpy="7.41596560408007E-17 1.33876788296791E-16 -2.44545873596083E-16" />
    <parent
      link="link_arm_l2" />
    <child
      link="link_arm_l1" />
    <axis
  xyz="0 0 1" />
    <limit effort="100" lower="0.0" upper="0.13" velocity="1.0"/>
    <dynamics damping="${joint_damping}" friction="${joint_friction}" spring_reference="${joint_spring_reference}" spring_stiffness="{joint_spring_stiffness}"/>
  </joint>
  
  <link
    name="link_arm_l0">
    <inertial>
      <origin
        xyz="0.0230715049668191 -0.00195115833662818 -0.0360646347160285"
        rpy="0 0 0" />
      <mass
        value="0.0101241250325294" />
      <inertia
        ixx="0.001"
        ixy="0"
        ixz="0"
        iyy="0.001"
        iyz="0"
        izz="0.001" />
    </inertial>
    <visual>
      <origin
        xyz="0 0 0"
        rpy="0 0 0" />
      <geometry>
        <mesh
          filename="package://stretch_description/meshes/link_arm_l0.dae" />
      </geometry>
    </visual>
    <collision>
      <origin
        xyz="0 0 0"
        rpy="0 0 0" />
      <geometry>
        <mesh
          filename="package://stretch_description/meshes/link_arm_l0.STL" />
      </geometry>
    </collision>
  </link>
  
  <joint
    name="joint_arm_l0"
    type="prismatic">
    <origin
      xyz="0 0 -0.0137499999999938"
      rpy="-3.05317390622457E-16 -4.23236224076729E-16 -2.68425135229209E-17" />
    <parent
      link="link_arm_l1" />
    <child
      link="link_arm_l0" />
    <axis
  xyz="0 0 1" />
    <limit effort="100" lower="0.0" upper="0.13" velocity="1.0"/>
    <dynamics damping="${joint_damping}" friction="${joint_friction}" spring_reference="${joint_spring_reference}" spring_stiffness="{joint_spring_stiffness}"/>
  </joint>
  
  <link
    name="link_wrist_yaw">
    <inertial>
      <origin
        xyz="-8.02795716750571E-06 1.93811447768422E-05 0.018946700595851"
        rpy="0 0 0" />
      <mass
        value="0.0405398981326229" />
      <inertia
        ixx="0.001"
        ixy="0"
        ixz="0"
        iyy="0.001"
        iyz="0"
        izz="0.001" />
    </inertial>
    <visual>
      <origin
        xyz="0 0 0"
        rpy="0 0 0" />
      <geometry>
        <mesh
          filename="package://stretch_description/meshes/link_wrist_yaw.dae" />
      </geometry>
    </visual>
    <collision>
      <origin
        xyz="0 0 0"
        rpy="0 0 0" />
      <geometry>
        <mesh
          filename="package://stretch_description/meshes/link_wrist_yaw.STL" />
      </geometry>
    </collision>
  </link>
  
  <joint
    name="joint_wrist_yaw"
    type="revolute">
    <origin
      xyz="0.083 -0.03075 0"
      rpy="1.5708 4.2595E-14 2.6415E-15" />
    <parent
      link="link_arm_l0" />
    <child
      link="link_wrist_yaw" />
    <axis
      xyz="0 0 -1" />
    <limit effort="100" lower="-1.75" upper="4.0" velocity="1.0"/>
    <dynamics damping="${joint_damping}" friction="${joint_friction}" spring_reference="${joint_spring_reference}" spring_stiffness="{joint_spring_stiffness}"/>
  </joint>
  
  <link
    name="link_head">
    <inertial>
      <origin
        xyz="0.0372933550588956 0.045509432985552 0.0281136801213409"
        rpy="0 0 0" />
      <mass
        value="0.00129454717596498" />
      <inertia
        ixx="0.001"
        ixy="0"
        ixz="0"
        iyy="0.001"
        iyz="0"
        izz="0.001" />
    </inertial>
    <visual>
      <origin
        xyz="0 0 0"
        rpy="0 0 0" />
      <geometry>
        <mesh
          filename="package://stretch_description/meshes/link_head.dae" />
      </geometry>
    </visual>
    <collision>
      <origin
        xyz="0 0 0"
        rpy="0 0 0" />
      <geometry>
        <mesh
          filename="package://stretch_description/meshes/link_head.STL" />
      </geometry>
    </collision>
  </link>

  <joint
    name="joint_head"
    type="fixed">
    <origin
      xyz="0 1.33 0"
      rpy="1.5708 -1.5615 3.1416" />
    <parent
      link="link_mast" />
    <child
      link="link_head" />
    <axis
      xyz="0 0 0" />
  </joint>

  <link
    name="link_head_pan">
    <inertial>
      <origin
        xyz="-0.00116200255310878 0.0130365621706306 0.00137629842298681"
        rpy="0 0 0" />
      <mass
        value="0.00035858341182617" />
      <inertia
        ixx="0.0001"
        ixy="0"
        ixz="0"
        iyy="0.0001"
        iyz="0"
        izz="0.0001" />
    </inertial>
    <visual>
      <origin
        xyz="0 0 0"
        rpy="0 0 0" />
      <geometry>
        <mesh
          filename="package://stretch_description/meshes/link_head_pan.dae" />
      </geometry>
    </visual>
    <collision>
      <origin
        xyz="0 0 0"
        rpy="0 0 0" />
      <geometry>
        <mesh
          filename="package://stretch_description/meshes/link_head_pan.STL" />
      </geometry>
    </collision>
  </link>

  <joint
    name="joint_head_pan"
    type="revolute">
    <origin
      xyz="0.135 0.0731 -0.003"
      rpy="-6.4986E-15 -6.068E-24 1.5708" />
    <parent
      link="link_head" />
    <child
      link="link_head_pan" />
    <axis
  xyz="0 0 1" />
    <dynamics damping="${joint_damping}" friction="${joint_friction}" spring_reference="${joint_spring_reference}" spring_stiffness="{joint_spring_stiffness}"/>
    <limit effort="100" lower="-3.9" upper="1.5" velocity="1.0"/>
  </joint>
  
  <link
    name="link_head_tilt">
    <inertial>
      <origin
        xyz="0.00920211049011871 -0.0279724762416447 0.0306580436227023"
        rpy="0 0 0" />
      <mass
        value="0.000101242408063442" />
      <inertia
        ixx="0.0001"
        ixy="0"
        ixz="0"
        iyy="0.0001"
        iyz="0"
        izz="0.0001" />
    </inertial>
    <visual>
      <origin
        xyz="0 0 0"
        rpy="0 0 0" />
      <geometry>
        <mesh
          filename="package://stretch_description/meshes/link_head_tilt.dae" />
      </geometry>
    </visual>
    <collision>
      <origin
        xyz="0 0 0"
        rpy="0 0 0" />
      <geometry>
        <mesh
          filename="package://stretch_description/meshes/link_head_tilt.STL" />
      </geometry>
    </collision>
  </link>
  
  <joint
    name="joint_head_tilt"
    type="revolute">
    <origin
      xyz="-0.0013 0.027507 -0.053311"
      rpy="1.5708 6.068E-24 -2.5165E-15" />
    <parent
      link="link_head_pan" />
    <child
      link="link_head_tilt" />
    <axis
      xyz="0 0 1" />
    <dynamics damping="${joint_damping}" friction="${joint_friction}" spring_reference="${joint_spring_reference}" spring_stiffness="{joint_spring_stiffness}"/>
    <limit effort="100" lower="-1.53" upper="0.79" velocity="1.0"/>
  </joint>

</robot>
